Workbook

Sheet 250822
A1: 8MW 해상기초 설계용 타워정보 | K1: WinDS3000/134 tower 정보 from 250617_3MW134_Decrypted.prj
A2: Upper | B2: Lower | C2: Wall | D2: Upper | E2: Upper | F2: Lower | G2: Lower | H2: Flange | I2: Flange | K2: Upper | L2: Lower | M2: Upper | N2: Lower | O2: Upper | P2: Upper | Q2: Lower | R2: Lower | S2: Flange | T2: Flange
A3: height | B3: height | C3: thick- | D3: outside | E3: inside | F3: outside | G3: inside | H3: Location | I3: Mass | K3: height | L3: height | M3: Wall | N3: Wall | O3: outside | P3: inside | Q3: outside | R3: inside | S3: Location | T3: Mass
A4: above | B4: above | C4: ness, | D4: diameter, | E4: diameter, | F4: diameter, | G4: diameter, | K4: above | L4: above | M4: thick- | N4: thick- | O4: diameter, | P4: diameter, | Q4: diameter, | R4: diameter,
A5: ground, | B5: ground, | C5: ti | D5: DO,i_UPR | E5: DI,i_UPR | F5: DO,i_LWR | G5: DI,i_LWR | K5: ground, | L5: ground, | M5: ness, | N5: ness, | O5: DO,i_UPR | P5: DI,i_UPR | Q5: DO,i_LWR | R5: DI,i_LWR
A6: Hi_UPR | B6: Hi_LWR | K6: Hi_UPR | L6: Hi_LWR | M6: ti | N6: ti
A7: [m] | B7: [m] | C7: [mm] | D7: [mm] | E7: [mm] | F7: [mm] | G7: [mm] | H7: [-] | I7: [kg] | K7: [m] | L7: [m] | M7: [mm] | N7: [mm] | O7: [m] | P7: [m] | Q7: [m] | R7: [m] | S7: [-] | T7: [kg] | U7: 무게
A8: 0.4 | B8: 0 | C8: 60 | D8: 7000 | E8: 6880 | F8: 7000 | G8: 6880 | H8: T-FLG | I8: 32902.39 | K8: 18 | L8: 15 | M8: 34 | N8: 34 | O8: 4.5 | P8: 4.432 | Q8: 4.5 | R8: 4.432 | U8: =PI()*(O8+P8)/2*(M8/1000)*(K8-L8)*7850 -> 11234.103
A9: 3.38 | B9: 0.4 | C9: 60 | D9: 6970.8913 | E9: 6850.8913 | F9: 7000 | G9: 6880 | K9: 20.75 | L9: 18 | M9: 34 | N9: 34 | O9: 4.5 | P9: 4.432 | Q9: 4.5 | R9: 4.432 | U9: =PI()*(O9+P9)/2*(M9/1000)*(K9-L9)*7850 -> 10297.928
A10: 6.36 | B10: 3.38 | C10: 59 | D10: 6941.7827 | E10: 6823.7827 | F10: 6970.8913 | G10: 6852.8913 | K10: 21 | L10: 20.75 | M10: 34 | N10: 34 | O10: 4.5 | P10: 4.432 | Q10: 4.5 | R10: 4.432 | S10: L-FLG | T10: 3685.565
A11: 8.36 | B11: 6.36 | C11: 59 | D11: 6922.2466 | E11: 6804.2466 | F11: 6941.7827 | G11: 6823.7827 | K11: 21.25 | L11: 21 | M11: 34 | N11: 34 | O11: 4.5 | P11: 4.432 | Q11: 4.5 | R11: 4.432 | S11: L-FLG | T11: 3685.565
A12: 9.555 | B12: 8.36 | C12: 58 | D12: 6910.5739 | E12: 6794.5739 | F12: 6922.2466 | G12: 6806.2466 | K12: 23.83 | L12: 21.25 | M12: 34 | N12: 34 | O12: 4.5 | P12: 4.432 | Q12: 4.5 | R12: 4.432 | U12: =PI()*(O12+P12)/2*(M12/1000)*(K12-L12)*7850 -> 9661.329
A13: 11.535 | B13: 9.555 | C13: 57 | D13: 6891.2332 | E13: 6777.2332 | F13: 6910.5739 | G13: 6796.5739 | K13: 25.8 | L13: 23.83 | M13: 32 | N13: 32 | O13: 4.5 | P13: 4.436 | Q13: 4.5 | R13: 4.436 | U13: =PI()*(O13+P13)/2*(M13/1000)*(K13-L13)*7850 -> 6946.2258
A14: 14.515 | B14: 11.535 | C14: 56 | D14: 6862.1245 | E14: 6750.1245 | F14: 6891.2332 | G14: 6779.2332 | K14: 28.4 | L14: 25.8 | M14: 30 | N14: 30 | O14: 4.5 | P14: 4.44 | Q14: 4.5 | R14: 4.44 | U14: =PI()*(O14+P14)/2*(M14/1000)*(K14-L14)*7850 -> 8598.4794
A15: 17.495 | B15: 14.515 | C15: 54 | D15: 6833.0159 | E15: 6725.0159 | F15: 6862.1245 | G15: 6754.1245 | K15: 31 | L15: 28.4 | M15: 28 | N15: 28 | O15: 4.5 | P15: 4.444 | Q15: 4.5 | R15: 4.444 | U15: =PI()*(O15+P15)/2*(M15/1000)*(K15-L15)*7850 -> 8028.8382
A16: 20.475 | B16: 17.495 | C16: 52 | D16: 6803.9072 | E16: 6699.9072 | F16: 6833.0159 | G16: 6729.0159 | K16: 33.6 | L16: 31 | M16: 26 | N16: 26 | O16: 4.5 | P16: 4.448 | Q16: 4.5 | R16: 4.448 | U16: =PI()*(O16+P16)/2*(M16/1000)*(K16-L16)*7850 -> 7458.684
A17: 20.875 | B17: 20.475 | C17: 51 | D17: 6800 | E17: 6698 | F17: 6803.9072 | G17: 6701.9072 | H17: L-FLG | I17: 15502.721 | K17: 36.2 | L17: 33.6 | M17: 26 | N17: 26 | O17: 4.5 | P17: 4.448 | Q17: 4.5 | R17: 4.448 | U17: =PI()*(O17+P17)/2*(M17/1000)*(K17-L17)*7850 -> 7458.684
A18: 21.275 | B18: 20.875 | C18: 51 | D18: 6800 | E18: 6698 | F18: 6800 | G18: 6698 | H18: L-FLG | I18: 15502.721 | K18: 38.8 | L18: 36.2 | M18: 26 | N18: 26 | O18: 4.5 | P18: 4.448 | Q18: 4.5 | R18: 4.448 | U18: =PI()*(O18+P18)/2*(M18/1000)*(K18-L18)*7850 -> 7458.684
A19: 24.255 | B19: 21.275 | C19: 48 | D19: 6690.9333 | E19: 6594.9333 | F19: 6800 | G19: 6704 | K19: 39 | L19: 38.8 | M19: 26 | N19: 26 | O19: 4.5 | P19: 4.448 | Q19: 4.5 | R19: 4.448 | S19: L-FLG | T19: 2751.025
A20: 27.235 | B20: 24.255 | C20: 48 | D20: 6581.8666 | E20: 6485.8666 | F20: 6690.9333 | G20: 6594.9333 | K20: 39.2 | L20: 39 | M20: 26 | N20: 26 | O20: 4.5 | P20: 4.448 | Q20: 4.5 | R20: 4.448 | S20: L-FLG | T20: 2751.025
A21: 30.215 | B21: 27.235 | C21: 48 | D21: 6472.7999 | E21: 6376.7999 | F21: 6581.8666 | G21: 6485.8666 | K21: 41.75 | L21: 39.2 | M21: 26 | N21: 26 | O21: 4.4428571 | P21: 4.3908571 | Q21: 4.5 | R21: 4.448 | U21: =PI()*(O21+P21)/2*(M21/1000)*(K21-L21)*7850 -> 7221.8159
A22: 33.195 | B22: 30.215 | C22: 47 | D22: 6363.7332 | E22: 6269.7332 | F22: 6472.7999 | G22: 6378.7999 | K22: 44.3 | L22: 41.75 | M22: 24 | N22: 24 | O22: 4.3857143 | P22: 4.3377143 | Q22: 4.4428571 | R22: 4.3948571 | U22: =PI()*(O22+P22)/2*(M22/1000)*(K22-L22)*7850 -> 6583.0653
A23: 36.175 | B23: 33.195 | C23: 47 | D23: 6254.6664 | E23: 6160.6664 | F23: 6363.7332 | G23: 6269.7332 | K23: 46.85 | L23: 44.3 | M23: 24 | N23: 24 | O23: 4.3285714 | P23: 4.2805714 | Q23: 4.3857143 | R23: 4.3377143 | U23: =PI()*(O23+P23)/2*(M23/1000)*(K23-L23)*7850 -> 6496.8205
A24: 39.155 | B24: 36.175 | C24: 47 | D24: 6145.5997 | E24: 6051.5997 | F24: 6254.6664 | G24: 6160.6664 | K24: 49.4 | L24: 46.85 | M24: 22 | N24: 22 | O24: 4.2714286 | P24: 4.2274286 | Q24: 4.3285714 | R24: 4.2845714 | U24: =PI()*(O24+P24)/2*(M24/1000)*(K24-L24)*7850 -> 5879.1281
A25: 42.135 | B25: 39.155 | C25: 46 | D25: 6036.533 | E25: 5944.533 | F25: 6145.5997 | G25: 6053.5997 | K25: 51.95 | L25: 49.4 | M25: 22 | N25: 22 | O25: 4.2142857 | P25: 4.1702857 | Q25: 4.2714286 | R25: 4.2274286 | U25: =PI()*(O25+P25)/2*(M25/1000)*(K25-L25)*7850 -> 5800.0704
A26: 45.115 | B26: 42.135 | C26: 45 | D26: 5927.4663 | E26: 5837.4663 | F26: 6036.533 | G26: 5946.533 | K26: 54.5 | L26: 51.95 | M26: 22 | N26: 22 | O26: 4.1571429 | P26: 4.1131429 | Q26: 4.2142857 | R26: 4.1702857 | U26: =PI()*(O26+P26)/2*(M26/1000)*(K26-L26)*7850 -> 5721.0127
A27: 48.095 | B27: 45.115 | C27: 44 | D27: 5818.3996 | E27: 5730.3996 | F27: 5927.4663 | G27: 5839.4663 | K27: 57.05 | L27: 54.5 | M27: 20 | N27: 20 | O27: 4.1 | P27: 4.06 | Q27: 4.1571429 | R27: 4.1171429 | U27: =PI()*(O27+P27)/2*(M27/1000)*(K27-L27)*7850 -> 5131.5654
A28: 51.075 | B28: 48.095 | C28: 43 | D28: 5709.3329 | E28: 5623.3329 | F28: 5818.3996 | G28: 5732.3996 | K28: 57.225 | L28: 57.05 | M28: 20 | N28: 20 | O28: 4.1 | P28: 4.06 | Q28: 4.1 | R28: 4.06 | S28: L-FLG | T28: 1807.995
A29: 51.33 | B29: 51.075 | C29: 43 | D29: 5700 | E29: 5614 | F29: 5709.3329 | G29: 5623.3329 | H29: L-FLG | I29: 6111.4858 | K29: 57.4 | L29: 57.225 | M29: 20 | N29: 20 | O29: 4.1 | P29: 4.06 | Q29: 4.1 | R29: 4.06 | S29: L-FLG | T29: 1807.995
A30: 51.585 | B30: 51.33 | C30: 43 | D30: 5700 | E30: 5614 | F30: 5700 | G30: 5614 | H30: L-FLG | I30: 6111.4858 | K30: 59.95 | L30: 57.4 | M30: 20 | N30: 20 | O30: 4.0323988 | P30: 3.9923988 | Q30: 4.1 | R30: 4.06 | U30: =PI()*(O30+P30)/2*(M30/1000)*(K30-L30)*7850 -> 5046.541
A31: 54.485 | B31: 51.585 | C31: 42 | D31: 5636.8683 | E31: 5552.8683 | F31: 5700 | G31: 5616 | K31: 62.5 | L31: 59.95 | M31: 20 | N31: 20 | O31: 3.9647977 | P31: 3.9247977 | Q31: 4.0323988 | R31: 3.9923988 | U31: =PI()*(O31+P31)/2*(M31/1000)*(K31-L31)*7850 -> 4961.5165
A32: 57.385 | B32: 54.485 | C32: 41 | D32: 5573.7366 | E32: 5491.7366 | F32: 5636.8683 | G32: 5554.8683 | K32: 65.05 | L32: 62.5 | M32: 20 | N32: 20 | O32: 3.8971965 | P32: 3.8571965 | Q32: 3.9647977 | R32: 3.9247977 | U32: =PI()*(O32+P32)/2*(M32/1000)*(K32-L32)*7850 -> 4876.4921
A33: 60.285 | B33: 57.385 | C33: 40 | D33: 5510.6049 | E33: 5430.6049 | F33: 5573.7366 | G33: 5493.7366 | K33: 67.6 | L33: 65.05 | M33: 18 | N33: 18 | O33: 3.8295954 | P33: 3.7935954 | Q33: 3.8971965 | R33: 3.8611965 | U33: =PI()*(O33+P33)/2*(M33/1000)*(K33-L33)*7850 -> 4314.5848
A34: 63.185 | B34: 60.285 | C34: 38 | D34: 5447.4732 | E34: 5371.4732 | F34: 5510.6049 | G34: 5434.6049 | K34: 70.15 | L34: 67.6 | M34: 18 | N34: 18 | O34: 3.7619942 | P34: 3.7259942 | Q34: 3.8295954 | R34: 3.7935954 | U34: =PI()*(O34+P34)/2*(M34/1000)*(K34-L34)*7850 -> 4238.0628
A35: 66.085 | B35: 63.185 | C35: 37 | D35: 5384.3415 | E35: 5310.3415 | F35: 5447.4732 | G35: 5373.4732 | K35: 72.7 | L35: 70.15 | M35: 18 | N35: 18 | O35: 3.6943931 | P35: 3.6583931 | Q35: 3.7619942 | R35: 3.7259942 | U35: =PI()*(O35+P35)/2*(M35/1000)*(K35-L35)*7850 -> 4161.5408
A36: 68.985 | B36: 66.085 | C36: 36 | D36: 5321.2098 | E36: 5249.2098 | F36: 5384.3415 | G36: 5312.3415 | K36: 75.25 | L36: 72.7 | M36: 16 | N36: 16 | O36: 3.6267919 | P36: 3.5947919 | Q36: 3.6943931 | R36: 3.6623931 | U36: =PI()*(O36+P36)/2*(M36/1000)*(K36-L36)*7850 -> 3633.1402
A37: 71.885 | B37: 68.985 | C37: 35.5 | D37: 5258.0781 | E37: 5187.0781 | F37: 5321.2098 | G37: 5250.2098 | K37: 77.8 | L37: 75.25 | M37: 16 | N37: 16 | O37: 3.5591908 | P37: 3.5271908 | Q37: 3.6267919 | R37: 3.5947919 | U37: =PI()*(O37+P37)/2*(M37/1000)*(K37-L37)*7850 -> 3565.1206
A38: 74.785 | B38: 71.885 | C38: 34.5 | D38: 5194.9464 | E38: 5125.9464 | F38: 5258.0781 | G38: 5189.0781 | K38: 80.35 | L38: 77.8 | M38: 16 | N38: 16 | O38: 3.4915896 | P38: 3.4595896 | Q38: 3.5591908 | R38: 3.5271908 | U38: =PI()*(O38+P38)/2*(M38/1000)*(K38-L38)*7850 -> 3497.1011
A39: 77.685 | B39: 74.785 | C39: 33.5 | D39: 5131.8147 | E39: 5064.8147 | F39: 5194.9464 | G39: 5127.9464 | K39: 82.9 | L39: 80.35 | M39: 16 | N39: 16 | O39: 3.4239885 | P39: 3.3919885 | Q39: 3.4915896 | R39: 3.4595896 | U39: =PI()*(O39+P39)/2*(M39/1000)*(K39-L39)*7850 -> 3429.0815
A40: 80.585 | B40: 77.685 | C40: 32.5 | D40: 5068.6829 | E40: 5003.6829 | F40: 5131.8147 | G40: 5066.8147 | K40: 85.239 | L40: 82.9 | M40: 16 | N40: 16 | O40: 3.361981 | P40: 3.329981 | Q40: 3.4239885 | R40: 3.3919885 | U40: =PI()*(O40+P40)/2*(M40/1000)*(K40-L40)*7850 -> 3088.1131
...

Sheet 20251016-검토 변경
B2: 모델 전달_251017 - 251001 하중 검토 결과 (DLC6.1)
B3: Upper | C3: Lower | D3: Upper | E3: Lower | F3: Upper | G3: Upper | H3: Lower | I3: Lower | J3: Flange | K3: Flange
B4: height | C4: height | D4: Wall | E4: Wall | F4: outside | G4: inside | H4: outside | I4: inside | J4: Location | K4: Mass
B5: above | C5: above | D5: thick- | E5: thick- | F5: diameter, | G5: diameter, | H5: diameter, | I5: diameter,
B6: ground, | C6: ground, | D6: ness, | E6: ness, | F6: DO,i_UPR | G6: DI,i_UPR | H6: DO,i_LWR | I6: DI,i_LWR
B7: Hi_UPR | C7: Hi_LWR | D7: ti | E7: ti | L7: 무게
B8: [m] | C8: [m] | D8: [mm] | E8: [mm] | F8: [m] | G8: [m] | H8: [m] | I8: [m] | J8: [-] | K8: [kg]
B9: 15.3 | C9: 15 | D9: 45 | E9: 45 | F9: 4500 | G9: 4410 | H9: 4500 | I9: 4410 | J9: L-FLG | K9: 7366.7761
B10: 17.4 | C10: 15.3 | D10: 44 | E10: 44 | F10: 4500 | G10: 4412 | H10: 4500 | I10: 4412 | L10: =PI()*(F10+G10)/2000*(D10/1000)*(B10-C10)*7850 -> 10153.989
B11: 19.5 | C11: 17.4 | D11: 42 | E11: 42 | F11: 4500 | G11: 4416 | H11: 4500 | I11: 4416 | L11: =PI()*(F11+G11)/2000*(D11/1000)*(B11-C11)*7850 -> 9696.7942
B12: 21.6 | C12: 19.5 | D12: 42 | E12: 42 | F12: 4500 | G12: 4416 | H12: 4500 | I12: 4416 | L12: =PI()*(F12+G12)/2000*(D12/1000)*(B12-C12)*7850 -> 9696.7942
B13: 23.7 | C13: 21.6 | D13: 39 | E13: 39 | F13: 4500 | G13: 4422 | H13: 4500 | I13: 4422 | L13: =PI()*(F13+G13)/2000*(D13/1000)*(B13-C13)*7850 -> 9010.2254
B14: 25.8 | C14: 23.7 | D14: 38 | E14: 38 | F14: 4500 | G14: 4424 | H14: 4500 | I14: 4424 | L14: =PI()*(F14+G14)/2000*(D14/1000)*(B14-C14)*7850 -> 8781.1619
B15: 28.4 | C15: 25.8 | D15: 37 | E15: 37 | F15: 4500 | G15: 4426 | H15: 4500 | I15: 4426 | L15: =PI()*(F15+G15)/2000*(D15/1000)*(B15-C15)*7850 -> 10588.184
B16: 31 | C16: 28.4 | D16: 36 | E16: 36 | F16: 4500 | G16: 4428 | H16: 4500 | I16: 4428 | L16: =PI()*(F16+G16)/2000*(D16/1000)*(B16-C16)*7850 -> 10304.325
B17: 33.6 | C17: 31 | D17: 35 | E17: 35 | F17: 4500 | G17: 4430 | H17: 4500 | I17: 4430 | L17: =PI()*(F17+G17)/2000*(D17/1000)*(B17-C17)*7850 -> 10020.338
B18: 36.2 | C18: 33.6 | D18: 34 | E18: 34 | F18: 4500 | G18: 4432 | H18: 4500 | I18: 4432 | L18: =PI()*(F18+G18)/2000*(D18/1000)*(B18-C18)*7850 -> 9736.223
B19: 38.75 | C19: 36.2 | D19: 33 | E19: 33 | F19: 4500 | G19: 4434 | H19: 4500 | I19: 4434 | L19: =PI()*(F19+G19)/2000*(D19/1000)*(B19-C19)*7850 -> 9270.2106
B20: 39 | C20: 38.75 | D20: 32 | E20: 32 | F20: 4500 | G20: 4436 | H20: 4500 | I20: 4436 | J20: L-FLG | K20: 3534.1739
B21: 39.25 | C21: 39 | D21: 32 | E21: 32 | F21: 4500 | G21: 4436 | H21: 4500 | I21: 4436 | J21: L-FLG | K21: 3534.1739
B22: 41.75 | C22: 39.25 | D22: 32 | E22: 32 | F22: 4444.3672 | G22: 4380.3672 | H22: 4500 | I22: 4436 | L22: =PI()*(F22+G22)/2000*(D22/1000)*(B22-C22)*7850 -> 8705.2483
B23: 44.3 | C23: 41.75 | D23: 32 | E23: 32 | F23: 4387.6217 | G23: 4323.6217 | H23: 4444.3672 | I23: 4380.3672 | L23: =PI()*(F23+G23)/2000*(D23/1000)*(B23-C23)*7850 -> 8765.1598
B24: 46.85 | C24: 44.3 | D24: 31 | E24: 31 | F24: 4330.8762 | G24: 4268.8762 | H24: 4387.6217 | I24: 4325.6217 | L24: =PI()*(F24+G24)/2000*(D24/1000)*(B24-C24)*7850 -> 8382.5733
B25: 49.4 | C25: 46.85 | D25: 30 | E25: 30 | F25: 4274.1307 | G25: 4214.1307 | H25: 4330.8762 | I25: 4270.8762 | L25: =PI()*(F25+G25)/2000*(D25/1000)*(B25-C25)*7850 -> 8006.998
B26: 51.95 | C26: 49.4 | D26: 30 | E26: 30 | F26: 4217.3853 | G26: 4157.3853 | H26: 4274.1307 | I26: 4214.1307 | L26: =PI()*(F26+G26)/2000*(D26/1000)*(B26-C26)*7850 -> 7899.9417
B27: 54.5 | C27: 51.95 | D27: 29 | E27: 29 | F27: 4160.6398 | G27: 4102.6398 | H27: 4217.3853 | I27: 4159.3853 | L27: =PI()*(F27+G27)/2000*(D27/1000)*(B27-C27)*7850 -> 7534.9462
B28: 57 | C28: 54.5 | D28: 29 | E28: 29 | F28: 4105.007 | G28: 4047.007 | H28: 4160.6398 | I28: 4102.6398 | L28: =PI()*(F28+G28)/2000*(D28/1000)*(B28-C28)*7850 -> 7287.733
B29: 57.225 | C29: 57 | D29: 28 | E29: 28 | F29: 4100 | G29: 4044 | H29: 4105.007 | I29: 4049.007 | J29: L-FLG | K29: 2463.6249
B30: 57.45 | C30: 57.225 | D30: 28 | E30: 28 | F30: 4100 | G30: 4044 | H30: 4100 | I30: 4044 | J30: L-FLG | K30: 2463.6249
B31: 59.95 | C31: 57.45 | D31: 28 | E31: 28 | F31: 4033.9978 | G31: 3977.9978 | H31: 4100 | I31: 4044 | L31: =PI()*(F31+G31)/2000*(D31/1000)*(B31-C31)*7850 -> 6915.5746
B32: 62.5 | C32: 59.95 | D32: 27 | E32: 27 | F32: 3966.6755 | G32: 3912.6755 | H32: 4033.9978 | I32: 3979.9978 | L32: =PI()*(F32+G32)/2000*(D32/1000)*(B32-C32)*7850 -> 6689.35
B33: 65.05 | C33: 62.5 | D33: 26 | E33: 26 | F33: 3899.3532 | G33: 3847.3532 | H33: 3966.6755 | I33: 3914.6755 | L33: =PI()*(F33+G33)/2000*(D33/1000)*(B33-C33)*7850 -> 6333.1556
B34: 67.6 | C34: 65.05 | D34: 26 | E34: 26 | F34: 3832.0309 | G34: 3780.0309 | H34: 3899.3532 | I34: 3847.3532 | L34: =PI()*(F34+G34)/2000*(D34/1000)*(B34-C34)*7850 -> 6223.0797
B35: 70.15 | C35: 67.6 | D35: 25 | E35: 25 | F35: 3764.7086 | G35: 3714.7086 | H35: 3832.0309 | I35: 3782.0309 | L35: =PI()*(F35+G35)/2000*(D35/1000)*(B35-C35)*7850 -> 5879.4606
B36: 72.7 | C36: 70.15 | D36: 24 | E36: 24 | F36: 3697.3863 | G36: 3649.3863 | H36: 3764.7086 | I36: 3716.7086 | L36: =PI()*(F36+G36)/2000*(D36/1000)*(B36-C36)*7850 -> 5544.183
B37: 75.25 | C37: 72.7 | D37: 23 | E37: 23 | F37: 3630.064 | G37: 3584.064 | H37: 3697.3863 | I37: 3651.3863 | L37: =PI()*(F37+G37)/2000*(D37/1000)*(B37-C37)*7850 -> 5217.247
B38: 77.8 | C38: 75.25 | D38: 23 | E38: 23 | F38: 3562.7417 | G38: 3516.7417 | H38: 3630.064 | I38: 3584.064 | L38: =PI()*(F38+G38)/2000*(D38/1000)*(B38-C38)*7850 -> 5119.8722
B39: 80.35 | C39: 77.8 | D39: 21 | E39: 21 | F39: 3495.4194 | G39: 3453.4194 | H39: 3562.7417 | I39: 3520.7417 | L39: =PI()*(F39+G39)/2000*(D39/1000)*(B39-C39)*7850 -> 4588.3998
B40: 82.9 | C40: 80.35 | D40: 20 | E40: 20 | F40: 3428.0972 | G40: 3388.0972 | H40: 3495.4194 | I40: 3455.4194 | L40: =PI()*(F40+G40)/2000*(D40/1000)*(B40-C40)*7850 -> 4286.4886
B41: 85.226 | C41: 82.9 | D41: 19 | E41: 19 | F41: 3366.6887 | G41: 3328.6887 | H41: 3428.0972 | I41: 3390.0972 | L41: =PI()*(F41+G41)/2000*(D41/1000)*(B41-C41)*7850 -> 3648.6139
...

Sheet 20251022-Floating Tower 2차
B2: 모델 전달_251017 - 251001 하중 검토 결과 (DLC6.1) | V2: 부유식 모델 2차_251022 (공진점 검토 후 변경) | AI2: 부유식 모델 2차_251023 - Dia 5.0m 로 변경 후 강도 검토 결과
B3: Upper | C3: Lower | D3: Upper | E3: Lower | F3: Upper | G3: Upper | H3: Lower | I3: Lower | J3: Flange | K3: Flange | V3: Upper | W3: Lower | X3: Upper | Y3: Lower | Z3: Upper | AA3: Upper | AB3: Lower | AC3: Lower | AD3: Flange | AE3: Flange | AI3: Upper | AJ3: Lower | AK3: Upper | AL3: Lower | AM3: Upper | AN3: Upper | AO3: Lower | AP3: Lower | AQ3: Flange | AR3: Flange
B4: height | C4: height | D4: Wall | E4: Wall | F4: outside | G4: inside | H4: outside | I4: inside | J4: Location | K4: Mass | V4: height | W4: height | X4: Wall | Y4: Wall | Z4: outside | AA4: inside | AB4: outside | AC4: inside | AD4: Location | AE4: Mass | AI4: height | AJ4: height | AK4: Wall | AL4: Wall | AM4: outside | AN4: inside | AO4: outside | AP4: inside | AQ4: Location | AR4: Mass
B5: above | C5: above | D5: thick- | E5: thick- | F5: diameter, | G5: diameter, | H5: diameter, | I5: diameter, | V5: above | W5: above | X5: thick- | Y5: thick- | Z5: diameter, | AA5: diameter, | AB5: diameter, | AC5: diameter, | AI5: above | AJ5: above | AK5: thick- | AL5: thick- | AM5: diameter, | AN5: diameter, | AO5: diameter, | AP5: diameter,
B6: ground, | C6: ground, | D6: ness, | E6: ness, | F6: DO,i_UPR | G6: DI,i_UPR | H6: DO,i_LWR | I6: DI,i_LWR | V6: ground, | W6: ground, | X6: ness, | Y6: ness, | Z6: DO,i_UPR | AA6: DI,i_UPR | AB6: DO,i_LWR | AC6: DI,i_LWR | AI6: ground, | AJ6: ground, | AK6: ness, | AL6: ness, | AM6: DO,i_UPR | AN6: DI,i_UPR | AO6: DO,i_LWR | AP6: DI,i_LWR
B7: Hi_UPR | C7: Hi_LWR | D7: ti | E7: ti | L7: 무게 | N7: Dout_upper | O7: Dout_lower | P7: t | Q7: I_upper | R7: Dout_upper | S7: t | T7: I_upper | V7: Hi_UPR | W7: Hi_LWR | X7: ti | Y7: ti | AF7: 무게 | AI7: Hi_UPR | AJ7: Hi_LWR | AK7: ti | AL7: ti
B8: [m] | C8: [m] | D8: [mm] | E8: [mm] | F8: [m] | G8: [m] | H8: [m] | I8: [m] | J8: [-] | K8: [kg] | M8: Height | P8: mm | Q8: m^4 | S8: mm | T8: m^4 | V8: [m] | W8: [m] | X8: [mm] | Y8: [mm] | Z8: [m] | AA8: [m] | AB8: [m] | AC8: [m] | AD8: [-] | AE8: [kg] | AF8: kg | AI8: [m] | AJ8: [m] | AK8: [mm] | AL8: [mm] | AM8: [m] | AN8: [m] | AO8: [m] | AP8: [m] | AQ8: [-] | AR8: [kg]
B9: 15.3 | C9: 15 | D9: 45 | E9: 45 | F9: 4500 | G9: 4410 | H9: 4500 | I9: 4410 | J9: L-FLG | K9: 7366.7761 | M9: =B9-$C$9 -> 0.3 | N9: =F9 -> 4500 | O9: =H9 -> 4500 | P9: 45 | Q9: =PI()/4*((N9/2000)^4-(N9/2000-P9/1000)^4) -> 1.5626432 | R9: 5000 | S9: 35 | T9: =PI()/4*((R9/2000)^4-(R9/2000-S9/1000)^4) -> 1.6823148 | V9: =B9 -> 15.3 | W9: =C9 -> 15 | X9: =S9 -> 35 | Y9: =S9 -> 35 | Z9: =R9 -> 5000 | AA9: =Z9-X9 -> 4965 | AB9: 5000 | AC9: =AB9-Y9 -> 4965 | AD9: L-FLG | AE9: 7366.7761 | AI9: 15.3 | AJ9: 15 | AK9: 36 | AL9: 36 | AM9: 5000 | AN9: 4930 | AO9: 5000 | AP9: 4930 | AQ9: L-FLG | AR9: 7439.1662 | AT9: 1 | AU9: =IF('20251110-불일치 수정'!F9=AM9,"-","CHANGE") -> - | AV9: =IF('20251110-불일치 수정'!G9=AN9,"-","CHANGE") -> CHANGE | AW9: =IF('20251110-불일치 수정'!H9=AO9,"-","CHANGE") -> - | AX9: =IF('20251110-불일치 수정'!I9=AP9,"-","CHANGE") -> CHANGE
B10: 17.4 | C10: 15.3 | D10: 44 | E10: 44 | F10: 4500 | G10: 4412 | H10: 4500 | I10: 4412 | L10: =PI()*(F10+G10)/2000*(D10/1000)*(B10-C10)*7850 -> 10153.989 | M10: =B10-$C$9 -> 2.4 | N10: =F10 -> 4500 | O10: =H10 -> 4500 | P10: 44 | Q10: =PI()/4*((N10/2000)^4-(N10/2000-P10/1000)^4) -> 1.52894 | R10: 5000 | S10: 34 | T10: =PI()/4*((R10/2000)^4-(R10/2000-S10/1000)^4) -> 1.6352317 | V10: =B10 -> 17.4 | W10: =C10 -> 15.3 | X10: =S10 -> 34 | Y10: =S10 -> 34 | Z10: =R10 -> 5000 | AA10: =Z10-X10 -> 4966 | AB10: =Z9 -> 5000 | AC10: =AB10-Y10 -> 4966 | AF10: =PI()*(Z10+AA10)/2000*(X10/1000)*(V10-W10)*7850 -> 8774.2222 | AI10: 17.4 | AJ10: 15.3 | AK10: 35 | AL10: 35 | AM10: 5000 | AN10: 4932 | AO10: 5000 | AP10: 4932 | AT10: 2 | AU10: =IF('20251110-불일치 수정'!F10=AM10,"-","CHANGE") -> - | AV10: =IF('20251110-불일치 수정'!G10=AN10,"-","CHANGE") -> CHANGE | AW10: =IF('20251110-불일치 수정'!H10=AO10,"-","CHANGE") -> - | AX10: =IF('20251110-불일치 수정'!I10=AP10,"-","CHANGE") -> CHANGE
B11: 19.5 | C11: 17.4 | D11: 42 | E11: 42 | F11: 4500 | G11: 4416 | H11: 4500 | I11: 4416 | L11: =PI()*(F11+G11)/2000*(D11/1000)*(B11-C11)*7850 -> 9696.7942 | M11: =B11-$C$9 -> 4.5 | N11: =F11 -> 4500 | O11: =H11 -> 4500 | P11: 42 | Q11: =PI()/4*((N11/2000)^4-(N11/2000-P11/1000)^4) -> 1.461396 | R11: 5000 | S11: 33 | T11: =PI()/4*((R11/2000)^4-(R11/2000-S11/1000)^4) -> 1.5880913 | V11: =B11 -> 19.5 | W11: =C11 -> 17.4 | X11: =S11 -> 33 | Y11: =S11 -> 33 | Z11: =R11 -> 5000 | AA11: =Z11-X11 -> 4967 | AB11: =Z10 -> 5000 | AC11: =AB11-Y11 -> 4967 | AF11: =PI()*(Z11+AA11)/2000*(X11/1000)*(V11-W11)*7850 -> 8517.0114 | AI11: 19.5 | AJ11: 17.4 | AK11: 34 | AL11: 34 | AM11: 5000 | AN11: 4932 | AO11: 5000 | AP11: 4932 | AT11: 3 | AU11: =IF('20251110-불일치 수정'!F11=AM11,"-","CHANGE") -> - | AV11: =IF('20251110-불일치 수정'!G11=AN11,"-","CHANGE") -> - | AW11: =IF('20251110-불일치 수정'!H11=AO11,"-","CHANGE") -> - | AX11: =IF('20251110-불일치 수정'!I11=AP11,"-","CHANGE") -> -
B12: 21.6 | C12: 19.5 | D12: 42 | E12: 42 | F12: 4500 | G12: 4416 | H12: 4500 | I12: 4416 | L12: =PI()*(F12+G12)/2000*(D12/1000)*(B12-C12)*7850 -> 9696.7942 | M12: =B12-$C$9 -> 6.6 | N12: =F12 -> 4500 | O12: =H12 -> 4500 | P12: 42 | Q12: =PI()/4*((N12/2000)^4-(N12/2000-P12/1000)^4) -> 1.461396 | R12: 5000 | S12: 33 | T12: =PI()/4*((R12/2000)^4-(R12/2000-S12/1000)^4) -> 1.5880913 | V12: =B12 -> 21.6 | W12: =C12 -> 19.5 | X12: =S12 -> 33 | Y12: =S12 -> 33 | Z12: =R12 -> 5000 | AA12: =Z12-X12 -> 4967 | AB12: =Z11 -> 5000 | AC12: =AB12-Y12 -> 4967 | AF12: =PI()*(Z12+AA12)/2000*(X12/1000)*(V12-W12)*7850 -> 8517.0114 | AI12: 21.6 | AJ12: 19.5 | AK12: 34 | AL12: 34 | AM12: 5000 | AN12: 4932 | AO12: 5000 | AP12: 4932 | AT12: 4 | AU12: =IF('20251110-불일치 수정'!F12=AM12,"-","CHANGE") -> - | AV12: =IF('20251110-불일치 수정'!G12=AN12,"-","CHANGE") -> - | AW12: =IF('20251110-불일치 수정'!H12=AO12,"-","CHANGE") -> - | AX12: =IF('20251110-불일치 수정'!I12=AP12,"-","CHANGE") -> -
B13: 23.7 | C13: 21.6 | D13: 39 | E13: 39 | F13: 4500 | G13: 4422 | H13: 4500 | I13: 4422 | L13: =PI()*(F13+G13)/2000*(D13/1000)*(B13-C13)*7850 -> 9010.2254 | M13: =B13-$C$9 -> 8.7 | N13: =F13 -> 4500 | O13: =H13 -> 4500 | P13: 39 | Q13: =PI()/4*((N13/2000)^4-(N13/2000-P13/1000)^4) -> 1.3597352 | R13: 5000 | S13: 31 | T13: =PI()/4*((R13/2000)^4-(R13/2000-S13/1000)^4) -> 1.4936384 | V13: =B13 -> 23.7 | W13: =C13 -> 21.6 | X13: =S13 -> 31 | Y13: =S13 -> 31 | Z13: =R13 -> 5000 | AA13: =Z13-X13 -> 4969 | AB13: =Z12 -> 5000 | AC13: =AB13-Y13 -> 4969 | AF13: =PI()*(Z13+AA13)/2000*(X13/1000)*(V13-W13)*7850 -> 8002.4343 | AI13: 23.7 | AJ13: 21.6 | AK13: 34 | AL13: 34 | AM13: 5000 | AN13: 4934 | AO13: 5000 | AP13: 4934 | AT13: 5 | AU13: =IF('20251110-불일치 수정'!F13=AM13,"-","CHANGE") -> - | AV13: =IF('20251110-불일치 수정'!G13=AN13,"-","CHANGE") -> CHANGE | AW13: =IF('20251110-불일치 수정'!H13=AO13,"-","CHANGE") -> - | AX13: =IF('20251110-불일치 수정'!I13=AP13,"-","CHANGE") -> CHANGE
B14: 25.8 | C14: 23.7 | D14: 38 | E14: 38 | F14: 4500 | G14: 4424 | H14: 4500 | I14: 4424 | L14: =PI()*(F14+G14)/2000*(D14/1000)*(B14-C14)*7850 -> 8781.1619 | M14: =B14-$C$9 -> 10.8 | N14: =F14 -> 4500 | O14: =H14 -> 4500 | P14: 38 | Q14: =PI()/4*((N14/2000)^4-(N14/2000-P14/1000)^4) -> 1.3257562 | R14: 5000 | S14: 30 | T14: =PI()/4*((R14/2000)^4-(R14/2000-S14/1000)^4) -> 1.4463258 | V14: =B14 -> 25.8 | W14: =C14 -> 23.7 | X14: =S14 -> 30 | Y14: =S14 -> 30 | Z14: =R14 -> 5000 | AA14: =Z14-X14 -> 4970 | AB14: =Z13 -> 5000 | AC14: =AB14-Y14 -> 4970 | AF14: =PI()*(Z14+AA14)/2000*(X14/1000)*(V14-W14)*7850 -> 7745.0681 | AI14: 25.8 | AJ14: 23.7 | AK14: 33 | AL14: 33 | AM14: 5000 | AN14: 4934 | AO14: 5000 | AP14: 4934 | AT14: 6 | AU14: =IF('20251110-불일치 수정'!F14=AM14,"-","CHANGE") -> - | AV14: =IF('20251110-불일치 수정'!G14=AN14,"-","CHANGE") -> - | AW14: =IF('20251110-불일치 수정'!H14=AO14,"-","CHANGE") -> - | AX14: =IF('20251110-불일치 수정'!I14=AP14,"-","CHANGE") -> -
B15: 28.4 | C15: 25.8 | D15: 37 | E15: 37 | F15: 4500 | G15: 4426 | H15: 4500 | I15: 4426 | L15: =PI()*(F15+G15)/2000*(D15/1000)*(B15-C15)*7850 -> 10588.184 | M15: =B15-$C$9 -> 13.4 | N15: =F15 -> 4500 | O15: =H15 -> 4500 | P15: 37 | Q15: =PI()/4*((N15/2000)^4-(N15/2000-P15/1000)^4) -> 1.2917311 | R15: 5000 | S15: 29 | T15: =PI()/4*((R15/2000)^4-(R15/2000-S15/1000)^4) -> 1.3989557 | V15: =B15 -> 28.4 | W15: =C15 -> 25.8 | X15: =S15 -> 29 | Y15: =S15 -> 29 | Z15: =R15 -> 5000 | AA15: =Z15-X15 -> 4971 | AB15: =Z14 -> 5000 | AC15: =AB15-Y15 -> 4971 | AF15: =PI()*(Z15+AA15)/2000*(X15/1000)*(V15-W15)*7850 -> 9270.424 | AI15: 28.4 | AJ15: 25.8 | AK15: 32 | AL15: 32 | AM15: 5000 | AN15: 4936 | AO15: 5000 | AP15: 4936 | AT15: 7 | AU15: =IF('20251110-불일치 수정'!F15=AM15,"-","CHANGE") -> - | AV15: =IF('20251110-불일치 수정'!G15=AN15,"-","CHANGE") -> - | AW15: =IF('20251110-불일치 수정'!H15=AO15,"-","CHANGE") -> - | AX15: =IF('20251110-불일치 수정'!I15=AP15,"-","CHANGE") -> -
B16: 31 | C16: 28.4 | D16: 36 | E16: 36 | F16: 4500 | G16: 4428 | H16: 4500 | I16: 4428 | L16: =PI()*(F16+G16)/2000*(D16/1000)*(B16-C16)*7850 -> 10304.325 | M16: =B16-$C$9 -> 16 | N16: =F16 -> 4500 | O16: =H16 -> 4500 | P16: 36 | Q16: =PI()/4*((N16/2000)^4-(N16/2000-P16/1000)^4) -> 1.2576598 | R16: 5000 | S16: 29 | T16: =PI()/4*((R16/2000)^4-(R16/2000-S16/1000)^4) -> 1.3989557 | V16: =B16 -> 31 | W16: =C16 -> 28.4 | X16: =S16 -> 29 | Y16: =S16 -> 29 | Z16: =R16 -> 5000 | AA16: =Z16-X16 -> 4971 | AB16: =Z15 -> 5000 | AC16: =AB16-Y16 -> 4971 | AF16: =PI()*(Z16+AA16)/2000*(X16/1000)*(V16-W16)*7850 -> 9270.424 | AI16: 31 | AJ16: 28.4 | AK16: 31 | AL16: 31 | AM16: 5000 | AN16: 4938 | AO16: 5000 | AP16: 4938 | AT16: 8 | AU16: =IF('20251110-불일치 수정'!F16=AM16,"-","CHANGE") -> - | AV16: =IF('20251110-불일치 수정'!G16=AN16,"-","CHANGE") -> - | AW16: =IF('20251110-불일치 수정'!H16=AO16,"-","CHANGE") -> - | AX16: =IF('20251110-불일치 수정'!I16=AP16,"-","CHANGE") -> -
B17: 33.6 | C17: 31 | D17: 35 | E17: 35 | F17: 4500 | G17: 4430 | H17: 4500 | I17: 4430 | L17: =PI()*(F17+G17)/2000*(D17/1000)*(B17-C17)*7850 -> 10020.338 | M17: =B17-$C$9 -> 18.6 | N17: =F17 -> 4500 | O17: =H17 -> 4500 | P17: 35 | Q17: =PI()/4*((N17/2000)^4-(N17/2000-P17/1000)^4) -> 1.2235423 | R17: 5000 | S17: 28 | T17: =PI()/4*((R17/2000)^4-(R17/2000-S17/1000)^4) -> 1.351528 | V17: =B17 -> 33.6 | W17: =C17 -> 31 | X17: =S17 -> 28 | Y17: =S17 -> 28 | Z17: =R17 -> 5000 | AA17: =Z17-X17 -> 4972 | AB17: =Z16 -> 5000 | AC17: =AB17-Y17 -> 4972 | AF17: =PI()*(Z17+AA17)/2000*(X17/1000)*(V17-W17)*7850 -> 8951.6518 | AI17: 33.6 | AJ17: 31 | AK17: 31 | AL17: 31 | AM17: 5000 | AN17: 4938 | AO17: 5000 | AP17: 4938 | AT17: 9 | AU17: =IF('20251110-불일치 수정'!F17=AM17,"-","CHANGE") -> - | AV17: =IF('20251110-불일치 수정'!G17=AN17,"-","CHANGE") -> - | AW17: =IF('20251110-불일치 수정'!H17=AO17,"-","CHANGE") -> - | AX17: =IF('20251110-불일치 수정'!I17=AP17,"-","CHANGE") -> -
B18: 36.2 | C18: 33.6 | D18: 34 | E18: 34 | F18: 4500 | G18: 4432 | H18: 4500 | I18: 4432 | L18: =PI()*(F18+G18)/2000*(D18/1000)*(B18-C18)*7850 -> 9736.223 | M18: =B18-$C$9 -> 21.2 | N18: =F18 -> 4500 | O18: =H18 -> 4500 | P18: 34 | Q18: =PI()/4*((N18/2000)^4-(N18/2000-P18/1000)^4) -> 1.1893786 | R18: 5000 | S18: 27 | T18: =PI()/4*((R18/2000)^4-(R18/2000-S18/1000)^4) -> 1.3040428 | V18: =B18 -> 36.2 | W18: =C18 -> 33.6 | X18: =S18 -> 27 | Y18: =S18 -> 27 | Z18: =R18 -> 5000 | AA18: =Z18-X18 -> 4973 | AB18: =Z17 -> 5000 | AC18: =AB18-Y18 -> 4973 | AF18: =PI()*(Z18+AA18)/2000*(X18/1000)*(V18-W18)*7850 -> 8632.8156 | AI18: 36.2 | AJ18: 33.6 | AK18: 30 | AL18: 30 | AM18: 5000 | AN18: 4940 | AO18: 5000 | AP18: 4940 | AT18: 10 | AU18: =IF('20251110-불일치 수정'!F18=AM18,"-","CHANGE") -> - | AV18: =IF('20251110-불일치 수정'!G18=AN18,"-","CHANGE") -> - | AW18: =IF('20251110-불일치 수정'!H18=AO18,"-","CHANGE") -> - | AX18: =IF('20251110-불일치 수정'!I18=AP18,"-","CHANGE") -> -
B19: 38.75 | C19: 36.2 | D19: 33 | E19: 33 | F19: 4500 | G19: 4434 | H19: 4500 | I19: 4434 | L19: =PI()*(F19+G19)/2000*(D19/1000)*(B19-C19)*7850 -> 9270.2106 | M19: =B19-$C$9 -> 23.75 | N19: =F19 -> 4500 | O19: =H19 -> 4500 | P19: 33 | Q19: =PI()/4*((N19/2000)^4-(N19/2000-P19/1000)^4) -> 1.1551686 | R19: 5000 | S19: 26 | T19: =PI()/4*((R19/2000)^4-(R19/2000-S19/1000)^4) -> 1.2564999 | V19: =B19 -> 38.75 | W19: =C19 -> 36.2 | X19: =S19 -> 26 | Y19: =S19 -> 26 | Z19: =R19 -> 5000 | AA19: =Z19-X19 -> 4974 | AB19: =Z18 -> 5000 | AC19: =AB19-Y19 -> 4974 | AF19: =PI()*(Z19+AA19)/2000*(X19/1000)*(V19-W19)*7850 -> 8154.0323 | AI19: 38.75 | AJ19: 36.2 | AK19: 29 | AL19: 29 | AM19: 5000 | AN19: 4942 | AO19: 5000 | AP19: 4942 | AT19: 11 | AU19: =IF('20251110-불일치 수정'!F19=AM19,"-","CHANGE") -> - | AV19: =IF('20251110-불일치 수정'!G19=AN19,"-","CHANGE") -> - | AW19: =IF('20251110-불일치 수정'!H19=AO19,"-","CHANGE") -> - | AX19: =IF('20251110-불일치 수정'!I19=AP19,"-","CHANGE") -> -
B20: 39 | C20: 38.75 | D20: 32 | E20: 32 | F20: 4500 | G20: 4436 | H20: 4500 | I20: 4436 | J20: L-FLG | K20: 3534.1739 | M20: =B20-$C$9 -> 24 | N20: =F20 -> 4500 | O20: =H20 -> 4500 | P20: 32 | Q20: =PI()/4*((N20/2000)^4-(N20/2000-P20/1000)^4) -> 1.1209123 | R20: 5000 | S20: 26 | T20: =PI()/4*((R20/2000)^4-(R20/2000-S20/1000)^4) -> 1.2564999 | V20: =B20 -> 39 | W20: =C20 -> 38.75 | X20: =S20 -> 26 | Y20: =S20 -> 26 | Z20: =R20 -> 5000 | AA20: =Z20-X20 -> 4974 | AB20: =Z19 -> 5000 | AC20: =AB20-Y20 -> 4974 | AD20: L-FLG | AE20: 3534.1739 | AI20: 39 | AJ20: 38.75 | AK20: 29 | AL20: 29 | AM20: 5000 | AN20: 4942 | AO20: 5000 | AP20: 4942 | AQ20: L-FLG | AR20: 3441.0786 | AT20: 12 | AU20: =IF('20251110-불일치 수정'!F20=AM20,"-","CHANGE") -> - | AV20: =IF('20251110-불일치 수정'!G20=AN20,"-","CHANGE") -> - | AW20: =IF('20251110-불일치 수정'!H20=AO20,"-","CHANGE") -> - | AX20: =IF('20251110-불일치 수정'!I20=AP20,"-","CHANGE") -> -
B21: 39.25 | C21: 39 | D21: 32 | E21: 32 | F21: 4500 | G21: 4436 | H21: 4500 | I21: 4436 | J21: L-FLG | K21: 3534.1739 | M21: =B21-$C$9 -> 24.25 | N21: =F21 -> 4500 | O21: =H21 -> 4500 | P21: 32 | Q21: =PI()/4*((N21/2000)^4-(N21/2000-P21/1000)^4) -> 1.1209123 | R21: 5000 | S21: 26 | T21: =PI()/4*((R21/2000)^4-(R21/2000-S21/1000)^4) -> 1.2564999 | V21: =B21 -> 39.25 | W21: =C21 -> 39 | X21: =S21 -> 26 | Y21: =S21 -> 26 | Z21: =R21 -> 5000 | AA21: =Z21-X21 -> 4974 | AB21: =Z20 -> 5000 | AC21: =AB21-Y21 -> 4974 | AD21: L-FLG | AE21: 3534.1739 | AI21: 39.25 | AJ21: 39 | AK21: 28 | AL21: 28 | AM21: 5000 | AN21: 4944 | AO21: 5000 | AP21: 4944 | AQ21: L-FLG | AR21: 3441.0786 | AT21: 13 | AU21: =IF('20251110-불일치 수정'!F21=AM21,"-","CHANGE") -> - | AV21: =IF('20251110-불일치 수정'!G21=AN21,"-","CHANGE") -> - | AW21: =IF('20251110-불일치 수정'!H21=AO21,"-","CHANGE") -> - | AX21: =IF('20251110-불일치 수정'!I21=AP21,"-","CHANGE") -> -
B22: 41.75 | C22: 39.25 | D22: 32 | E22: 32 | F22: 4444.3672 | G22: 4380.3672 | H22: 4500 | I22: 4436 | L22: =PI()*(F22+G22)/2000*(D22/1000)*(B22-C22)*7850 -> 8705.2483 | M22: =B22-$C$9 -> 26.75 | N22: =F22 -> 4444.3672 | O22: =H22 -> 4500 | P22: 32 | Q22: =PI()/4*((N22/2000)^4-(N22/2000-P22/1000)^4) -> 1.0795621 | R22: 5000 | S22: 25 | T22: =PI()/4*((R22/2000)^4-(R22/2000-S22/1000)^4) -> 1.2088993 | V22: =B22 -> 41.75 | W22: =C22 -> 39.25 | X22: =S22 -> 25 | Y22: =S22 -> 25 | Z22: =R22 -> 5000 | AA22: =Z22-X22 -> 4975 | AB22: =Z21 -> 5000 | AC22: =AB22-Y22 -> 4975 | AF22: =PI()*(Z22+AA22)/2000*(X22/1000)*(V22-W22)*7850 -> 7687.4527 | AI22: 41.75 | AJ22: 39.25 | AK22: 28 | AL22: 28 | AM22: 5000 | AN22: 4944 | AO22: 5000 | AP22: 4944 | AT22: 14 | AU22: =IF('20251110-불일치 수정'!F22=AM22,"-","CHANGE") -> - | AV22: =IF('20251110-불일치 수정'!G22=AN22,"-","CHANGE") -> - | AW22: =IF('20251110-불일치 수정'!H22=AO22,"-","CHANGE") -> - | AX22: =IF('20251110-불일치 수정'!I22=AP22,"-","CHANGE") -> -
B23: 44.3 | C23: 41.75 | D23: 32 | E23: 32 | F23: 4387.6217 | G23: 4323.6217 | H23: 4444.3672 | I23: 4380.3672 | L23: =PI()*(F23+G23)/2000*(D23/1000)*(B23-C23)*7850 -> 8765.1598 | M23: =B23-$C$9 -> 29.3 | N23: =F23 -> 4387.6217 | O23: =H23 -> 4444.3672 | P23: 32 | Q23: =PI()/4*((N23/2000)^4-(N23/2000-P23/1000)^4) -> 1.0384456 | R23: 5000 | S23: 24 | T23: =PI()/4*((R23/2000)^4-(R23/2000-S23/1000)^4) -> 1.161241 | V23: =B23 -> 44.3 | W23: =C23 -> 41.75 | X23: =S23 -> 24 | Y23: =S23 -> 24 | Z23: =R23 -> 5000 | AA23: =Z23-X23 -> 4976 | AB23: =Z22 -> 5000 | AC23: =AB23-Y23 -> 4976 | AF23: =PI()*(Z23+AA23)/2000*(X23/1000)*(V23-W23)*7850 -> 7528.3083 | AI23: 44.3 | AJ23: 41.75 | AK23: 27 | AL23: 27 | AM23: 5000 | AN23: 4946 | AO23: 5000 | AP23: 4946 | AT23: 15 | AU23: =IF('20251110-불일치 수정'!F23=AM23,"-","CHANGE") -> - | AV23: =IF('20251110-불일치 수정'!G23=AN23,"-","CHANGE") -> - | AW23: =IF('20251110-불일치 수정'!H23=AO23,"-","CHANGE") -> - | AX23: =IF('20251110-불일치 수정'!I23=AP23,"-","CHANGE") -> -
B24: 46.85 | C24: 44.3 | D24: 31 | E24: 31 | F24: 4330.8762 | G24: 4268.8762 | H24: 4387.6217 | I24: 4325.6217 | L24: =PI()*(F24+G24)/2000*(D24/1000)*(B24-C24)*7850 -> 8382.5733 | M24: =B24-$C$9 -> 31.85 | N24: =F24 -> 4330.8762 | O24: =H24 -> 4387.6217 | P24: 31 | Q24: =PI()/4*((N24/2000)^4-(N24/2000-P24/1000)^4) -> 0.96785882 | R24: 5000 | S24: 23 | T24: =PI()/4*((R24/2000)^4-(R24/2000-S24/1000)^4) -> 1.1135249 | V24: =B24 -> 46.85 | W24: =C24 -> 44.3 | X24: =S24 -> 23 | Y24: =S24 -> 23 | Z24: =R24 -> 5000 | AA24: =Z24-X24 -> 4977 | AB24: =Z23 -> 5000 | AC24: =AB24-Y24 -> 4977 | AF24: =PI()*(Z24+AA24)/2000*(X24/1000)*(V24-W24)*7850 -> 7215.352 | AI24: 46.85 | AJ24: 44.3 | AK24: 26 | AL24: 26 | AM24: 5000 | AN24: 4948 | AO24: 5000 | AP24: 4948 | AT24: 16 | AU24: =IF('20251110-불일치 수정'!F24=AM24,"-","CHANGE") -> - | AV24: =IF('20251110-불일치 수정'!G24=AN24,"-","CHANGE") -> - | AW24: =IF('20251110-불일치 수정'!H24=AO24,"-","CHANGE") -> - | AX24: =IF('20251110-불일치 수정'!I24=AP24,"-","CHANGE") -> -
B25: 49.4 | C25: 46.85 | D25: 30 | E25: 30 | F25: 4274.1307 | G25: 4214.1307 | H25: 4330.8762 | I25: 4270.8762 | L25: =PI()*(F25+G25)/2000*(D25/1000)*(B25-C25)*7850 -> 8006.998 | M25: =B25-$C$9 -> 34.4 | N25: =F25 -> 4274.1307 | O25: =H25 -> 4330.8762 | P25: 30 | Q25: =PI()/4*((N25/2000)^4-(N25/2000-P25/1000)^4) -> 0.90067706 | R25: 5000 | S25: 22 | T25: =PI()/4*((R25/2000)^4-(R25/2000-S25/1000)^4) -> 1.0657509 | V25: =B25 -> 49.4 | W25: =C25 -> 46.85 | X25: =S25 -> 22 | Y25: =S25 -> 22 | Z25: =R25 -> 5000 | AA25: =Z25-X25 -> 4978 | AB25: =Z24 -> 5000 | AC25: =AB25-Y25 -> 4978 | AF25: =PI()*(Z25+AA25)/2000*(X25/1000)*(V25-W25)*7850 -> 6902.3328 | AI25: 49.4 | AJ25: 46.85 | AK25: 26 | AL25: 26 | AM25: 5000 | AN25: 4950 | AO25: 5000 | AP25: 4950 | AT25: 17 | AU25: =IF('20251110-불일치 수정'!F25=AM25,"-","CHANGE") -> - | AV25: =IF('20251110-불일치 수정'!G25=AN25,"-","CHANGE") -> CHANGE | AW25: =IF('20251110-불일치 수정'!H25=AO25,"-","CHANGE") -> - | AX25: =IF('20251110-불일치 수정'!I25=AP25,"-","CHANGE") -> CHANGE
B26: 51.95 | C26: 49.4 | D26: 30 | E26: 30 | F26: 4217.3853 | G26: 4157.3853 | H26: 4274.1307 | I26: 4214.1307 | L26: =PI()*(F26+G26)/2000*(D26/1000)*(B26-C26)*7850 -> 7899.9417 | M26: =B26-$C$9 -> 36.95 | N26: =F26 -> 4217.3853 | O26: =H26 -> 4274.1307 | P26: 30 | Q26: =PI()/4*((N26/2000)^4-(N26/2000-P26/1000)^4) -> 0.86503203 | R26: 5000 | S26: 21 | T26: =PI()/4*((R26/2000)^4-(R26/2000-S26/1000)^4) -> 1.0179192 | V26: =B26 -> 51.95 | W26: =C26 -> 49.4 | X26: =S26 -> 21 | Y26: =S26 -> 21 | Z26: =R26 -> 5000 | AA26: =Z26-X26 -> 4979 | AB26: =Z25 -> 5000 | AC26: =AB26-Y26 -> 4979 | AF26: =PI()*(Z26+AA26)/2000*(X26/1000)*(V26-W26)*7850 -> 6589.2507 | AI26: 51.95 | AJ26: 49.4 | AK26: 25 | AL26: 25 | AM26: 5000 | AN26: 4950 | AO26: 5000 | AP26: 4950 | AT26: 18 | AU26: =IF('20251110-불일치 수정'!F26=AM26,"-","CHANGE") -> - | AV26: =IF('20251110-불일치 수정'!G26=AN26,"-","CHANGE") -> - | AW26: =IF('20251110-불일치 수정'!H26=AO26,"-","CHANGE") -> - | AX26: =IF('20251110-불일치 수정'!I26=AP26,"-","CHANGE") -> -
B27: 54.5 | C27: 51.95 | D27: 29 | E27: 29 | F27: 4160.6398 | G27: 4102.6398 | H27: 4217.3853 | I27: 4159.3853 | L27: =PI()*(F27+G27)/2000*(D27/1000)*(B27-C27)*7850 -> 7534.9462 | M27: =B27-$C$9 -> 39.5 | N27: =F27 -> 4160.6398 | O27: =H27 -> 4217.3853 | P27: 29 | Q27: =PI()/4*((N27/2000)^4-(N27/2000-P27/1000)^4) -> 0.80324241 | R27: 5000 | S27: 20 | T27: =PI()/4*((R27/2000)^4-(R27/2000-S27/1000)^4) -> 0.97002944 | V27: =B27 -> 54.5 | W27: =C27 -> 51.95 | X27: =S27 -> 20 | Y27: =S27 -> 20 | Z27: =R27 -> 5000 | AA27: =Z27-X27 -> 4980 | AB27: =Z26 -> 5000 | AC27: =AB27-Y27 -> 4980 | AF27: =PI()*(Z27+AA27)/2000*(X27/1000)*(V27-W27)*7850 -> 6276.1057 | AI27: 54.5 | AJ27: 51.95 | AK27: 24 | AL27: 24 | AM27: 5000 | AN27: 4952 | AO27: 5000 | AP27: 4952 | AT27: 19 | AU27: =IF('20251110-불일치 수정'!F27=AM27,"-","CHANGE") -> - | AV27: =IF('20251110-불일치 수정'!G27=AN27,"-","CHANGE") -> - | AW27: =IF('20251110-불일치 수정'!H27=AO27,"-","CHANGE") -> - | AX27: =IF('20251110-불일치 수정'!I27=AP27,"-","CHANGE") -> -
B28: 57 | C28: 54.5 | D28: 29 | E28: 29 | F28: 4105.007 | G28: 4047.007 | H28: 4160.6398 | I28: 4102.6398 | L28: =PI()*(F28+G28)/2000*(D28/1000)*(B28-C28)*7850 -> 7287.733 | M28: =B28-$C$9 -> 42 | N28: =F28 -> 4105.007 | O28: =H28 -> 4160.6398 | P28: 29 | Q28: =PI()/4*((N28/2000)^4-(N28/2000-P28/1000)^4) -> 0.77123125 | R28: 5000 | S28: 20 | T28: =PI()/4*((R28/2000)^4-(R28/2000-S28/1000)^4) -> 0.97002944 | V28: =B28 -> 57 | W28: =C28 -> 54.5 | X28: =S28 -> 20 | Y28: =S28 -> 20 | Z28: =R28 -> 5000 | AA28: =Z28-X28 -> 4980 | AB28: =Z27 -> 5000 | AC28: =AB28-Y28 -> 4980 | AF28: =PI()*(Z28+AA28)/2000*(X28/1000)*(V28-W28)*7850 -> 6153.0448 | AI28: 57 | AJ28: 54.5 | AK28: 23 | AL28: 23 | AM28: 5000 | AN28: 4954 | AO28: 5000 | AP28: 4954 | AT28: 20 | AU28: =IF('20251110-불일치 수정'!F28=AM28,"-","CHANGE") -> - | AV28: =IF('20251110-불일치 수정'!G28=AN28,"-","CHANGE") -> - | AW28: =IF('20251110-불일치 수정'!H28=AO28,"-","CHANGE") -> - | AX28: =IF('20251110-불일치 수정'!I28=AP28,"-","CHANGE") -> -
B29: 57.225 | C29: 57 | D29: 28 | E29: 28 | F29: 4100 | G29: 4044 | H29: 4105.007 | I29: 4049.007 | J29: L-FLG | K29: 2463.6249 | M29: =B29-$C$9 -> 42.225 | N29: =F29 -> 4100 | O29: =H29 -> 4105.007 | P29: 28 | Q29: =PI()/4*((N29/2000)^4-(N29/2000-P29/1000)^4) -> 0.74244068 | R29: 5000 | S29: 29 | T29: =PI()/4*((R29/2000)^4-(R29/2000-S29/1000)^4) -> 1.3989557 | V29: =B29 -> 57.225 | W29: =C29 -> 57 | X29: =S29 -> 29 | Y29: =S29 -> 29 | Z29: =R29 -> 5000 | AA29: =Z29-X29 -> 4971 | AB29: =Z28 -> 5000 | AC29: =AB29-Y29 -> 4971 | AD29: L-FLG | AE29: 2463.6249 | AI29: 57.225 | AJ29: 57 | AK29: 22 | AL29: 22 | AM29: 5000 | AN29: 4956 | AO29: 5000 | AP29: 4956 | AQ29: L-FLG | AR29: 3146.132 | AT29: 21 | AU29: =IF('20251110-불일치 수정'!F29=AM29,"-","CHANGE") -> - | AV29: =IF('20251110-불일치 수정'!G29=AN29,"-","CHANGE") -> - | AW29: =IF('20251110-불일치 수정'!H29=AO29,"-","CHANGE") -> - | AX29: =IF('20251110-불일치 수정'!I29=AP29,"-","CHANGE") -> -
B30: 57.45 | C30: 57.225 | D30: 28 | E30: 28 | F30: 4100 | G30: 4044 | H30: 4100 | I30: 4044 | J30: L-FLG | K30: 2463.6249 | M30: =B30-$C$9 -> 42.45 | N30: =F30 -> 4100 | O30: =H30 -> 4100 | P30: 28 | Q30: =PI()/4*((N30/2000)^4-(N30/2000-P30/1000)^4) -> 0.74244068 | R30: 5000 | S30: 20 | T30: =PI()/4*((R30/2000)^4-(R30/2000-S30/1000)^4) -> 0.97002944 | V30: =B30 -> 57.45 | W30: =C30 -> 57.225 | X30: =S30 -> 20 | Y30: =S30 -> 20 | Z30: =R30 -> 5000 | AA30: =Z30-X30 -> 4980 | AB30: =Z29 -> 5000 | AC30: =AB30-Y30 -> 4980 | AD30: L-FLG | AE30: 2463.6249 | AI30: 57.45 | AJ30: 57.225 | AK30: 22 | AL30: 22 | AM30: 5000 | AN30: 4956 | AO30: 5000 | AP30: 4956 | AQ30: L-FLG | AR30: 3146.132 | AT30: 22 | AU30: =IF('20251110-불일치 수정'!F30=AM30,"-","CHANGE") -> - | AV30: =IF('20251110-불일치 수정'!G30=AN30,"-","CHANGE") -> - | AW30: =IF('20251110-불일치 수정'!H30=AO30,"-","CHANGE") -> - | AX30: =IF('20251110-불일치 수정'!I30=AP30,"-","CHANGE") -> -
B31: 59.95 | C31: 57.45 | D31: 28 | E31: 28 | F31: 4033.9978 | G31: 3977.9978 | H31: 4100 | I31: 4044 | L31: =PI()*(F31+G31)/2000*(D31/1000)*(B31-C31)*7850 -> 6915.5746 | M31: =B31-$C$9 -> 44.95 | N31: =F31 -> 4033.9978 | O31: =H31 -> 4100 | P31: 28 | Q31: =PI()/4*((N31/2000)^4-(N31/2000-P31/1000)^4) -> 0.70692158 | R31: 4800 | S31: 20 | T31: =PI()/4*((R31/2000)^4-(R31/2000-S31/1000)^4) -> 0.85779039 | V31: =B31 -> 59.95 | W31: =C31 -> 57.45 | X31: =S31 -> 20 | Y31: =S31 -> 20 | Z31: =R31 -> 4800 | AA31: =Z31-X31 -> 4780 | AB31: =Z30 -> 5000 | AC31: =AB31-Y31 -> 4980 | AF31: =PI()*(Z31+AA31)/2000*(X31/1000)*(V31-W31)*7850 -> 5906.4298 | AI31: 59.95 | AJ31: 57.45 | AK31: 22 | AL31: 22 | AM31: 4859.7452 | AN31: 4815.7452 | AO31: 5000 | AP31: 4956 | AT31: 23 | AU31: =IF('20251110-불일치 수정'!F31=AM31,"-","CHANGE") -> - | AV31: =IF('20251110-불일치 수정'!G31=AN31,"-","CHANGE") -> - | AW31: =IF('20251110-불일치 수정'!H31=AO31,"-","CHANGE") -> - | AX31: =IF('20251110-불일치 수정'!I31=AP31,"-","CHANGE") -> -
B32: 62.5 | C32: 59.95 | D32: 27 | E32: 27 | F32: 3966.6755 | G32: 3912.6755 | H32: 4033.9978 | I32: 3979.9978 | L32: =PI()*(F32+G32)/2000*(D32/1000)*(B32-C32)*7850 -> 6689.35 | M32: =B32-$C$9 -> 47.5 | N32: =F32 -> 3966.6755 | O32: =H32 -> 4033.9978 | P32: 27 | Q32: =PI()/4*((N32/2000)^4-(N32/2000-P32/1000)^4) -> 0.6483737 | R32: 4600 | S32: 20 | T32: =PI()/4*((R32/2000)^4-(R32/2000-S32/1000)^4) -> 0.75456142 | V32: =B32 -> 62.5 | W32: =C32 -> 59.95 | X32: =S32 -> 20 | Y32: =S32 -> 20 | Z32: =R32 -> 4600 | AA32: =Z32-X32 -> 4580 | AB32: =Z31 -> 4800 | AC32: =AB32-Y32 -> 4780 | AF32: =PI()*(Z32+AA32)/2000*(X32/1000)*(V32-W32)*7850 -> 5773.0111 | AI32: 62.5 | AJ32: 59.95 | AK32: 22 | AL32: 22 | AM32: 4716.6854 | AN32: 4672.6854 | AO32: 4859.7452 | AP32: 4815.7452 | AT32: 24 | AU32: =IF('20251110-불일치 수정'!F32=AM32,"-","CHANGE") -> - | AV32: =IF('20251110-불일치 수정'!G32=AN32,"-","CHANGE") -> - | AW32: =IF('20251110-불일치 수정'!H32=AO32,"-","CHANGE") -> - | AX32: =IF('20251110-불일치 수정'!I32=AP32,"-","CHANGE") -> -
B33: 65.05 | C33: 62.5 | D33: 26 | E33: 26 | F33: 3899.3532 | G33: 3847.3532 | H33: 3966.6755 | I33: 3914.6755 | L33: =PI()*(F33+G33)/2000*(D33/1000)*(B33-C33)*7850 -> 6333.1556 | M33: =B33-$C$9 -> 50.05 | N33: =F33 -> 3899.3532 | O33: =H33 -> 3966.6755 | P33: 26 | Q33: =PI()/4*((N33/2000)^4-(N33/2000-P33/1000)^4) -> 0.5933543 | R33: 4200 | S33: 21 | T33: =PI()/4*((R33/2000)^4-(R33/2000-S33/1000)^4) -> 0.60187632 | V33: =B33 -> 65.05 | W33: =C33 -> 62.5 | X33: =S33 -> 21 | Y33: =S33 -> 21 | Z33: =R33 -> 4200 | AA33: =Z33-X33 -> 4179 | AB33: =Z32 -> 4600 | AC33: =AB33-Y33 -> 4579 | AF33: =PI()*(Z33+AA33)/2000*(X33/1000)*(V33-W33)*7850 -> 5532.7519 | AI33: 65.05 | AJ33: 62.5 | AK33: 22 | AL33: 22 | AM33: 4573.6255 | AN33: 4529.6255 | AO33: 4716.6854 | AP33: 4672.6854 | AT33: 25 | AU33: =IF('20251110-불일치 수정'!F33=AM33,"-","CHANGE") -> - | AV33: =IF('20251110-불일치 수정'!G33=AN33,"-","CHANGE") -> - | AW33: =IF('20251110-불일치 수정'!H33=AO33,"-","CHANGE") -> - | AX33: =IF('20251110-불일치 수정'!I33=AP33,"-","CHANGE") -> -
B34: 67.6 | C34: 65.05 | D34: 26 | E34: 26 | F34: 3832.0309 | G34: 3780.0309 | H34: 3899.3532 | I34: 3847.3532 | L34: =PI()*(F34+G34)/2000*(D34/1000)*(B34-C34)*7850 -> 6223.0797 | M34: =B34-$C$9 -> 52.6 | N34: =F34 -> 3832.0309 | O34: =H34 -> 3899.3532 | P34: 26 | Q34: =PI()/4*((N34/2000)^4-(N34/2000-P34/1000)^4) -> 0.56295078 | R34: 4000 | S34: 23 | T34: =PI()/4*((R34/2000)^4-(R34/2000-S34/1000)^4) -> 0.56815786 | V34: =B34 -> 67.6 | W34: =C34 -> 65.05 | X34: =S34 -> 23 | Y34: =S34 -> 23 | Z34: =R34 -> 4000 | AA34: =Z34-X34 -> 3977 | AB34: =Z33 -> 4200 | AC34: =AB34-Y34 -> 4177 | AF34: =PI()*(Z34+AA34)/2000*(X34/1000)*(V34-W34)*7850 -> 5768.9549 | AI34: 67.6 | AJ34: 65.05 | AK34: 23 | AL34: 23 | AM34: 4430.5656 | AN34: 4384.5656 | AO34: 4573.6255 | AP34: 4527.6255 | AT34: 26 | AU34: =IF('20251110-불일치 수정'!F34=AM34,"-","CHANGE") -> - | AV34: =IF('20251110-불일치 수정'!G34=AN34,"-","CHANGE") -> - | AW34: =IF('20251110-불일치 수정'!H34=AO34,"-","CHANGE") -> - | AX34: =IF('20251110-불일치 수정'!I34=AP34,"-","CHANGE") -> -
B35: 70.15 | C35: 67.6 | D35: 25 | E35: 25 | F35: 3764.7086 | G35: 3714.7086 | H35: 3832.0309 | I35: 3782.0309 | L35: =PI()*(F35+G35)/2000*(D35/1000)*(B35-C35)*7850 -> 5879.4606 | M35: =B35-$C$9 -> 55.15 | N35: =F35 -> 3764.7086 | O35: =H35 -> 3832.0309 | P35: 25 | Q35: =PI()/4*((N35/2000)^4-(N35/2000-P35/1000)^4) -> 0.51349071 | R35: 3764.7086 | S35: 25 | T35: =PI()/4*((R35/2000)^4-(R35/2000-S35/1000)^4) -> 0.51349071 | V35: =B35 -> 70.15 | W35: =C35 -> 67.6 | X35: =S35 -> 25 | Y35: =S35 -> 25 | Z35: =R35 -> 3764.7086 | AA35: =Z35-X35 -> 3739.7086 | AB35: =Z34 -> 4000 | AC35: =AB35-Y35 -> 3975 | AF35: =PI()*(Z35+AA35)/2000*(X35/1000)*(V35-W35)*7850 -> 5899.1127 | AI35: 70.15 | AJ35: 67.6 | AK35: 25 | AL35: 25 | AM35: 4287.5058 | AN35: 4237.5058 | AO35: 4430.5656 | AP35: 4380.5656 | AT35: 27 | AU35: =IF('20251110-불일치 수정'!F35=AM35,"-","CHANGE") -> - | AV35: =IF('20251110-불일치 수정'!G35=AN35,"-","CHANGE") -> - | AW35: =IF('20251110-불일치 수정'!H35=AO35,"-","CHANGE") -> - | AX35: =IF('20251110-불일치 수정'!I35=AP35,"-","CHANGE") -> -
B36: 72.7 | C36: 70.15 | D36: 24 | E36: 24 | F36: 3697.3863 | G36: 3649.3863 | H36: 3764.7086 | I36: 3716.7086 | L36: =PI()*(F36+G36)/2000*(D36/1000)*(B36-C36)*7850 -> 5544.183 | M36: =B36-$C$9 -> 57.7 | N36: =F36 -> 3697.3863 | O36: =H36 -> 3764.7086 | P36: 24 | Q36: =PI()/4*((N36/2000)^4-(N36/2000-P36/1000)^4) -> 0.46718563 | R36: 3697.3863 | S36: 24 | T36: =PI()/4*((R36/2000)^4-(R36/2000-S36/1000)^4) -> 0.46718563 | V36: =B36 -> 72.7 | W36: =C36 -> 70.15 | X36: =S36 -> 24 | Y36: =S36 -> 24 | Z36: =R36 -> 3697.3863 | AA36: =Z36-X36 -> 3673.3863 | AB36: =Z35 -> 3764.7086 | AC36: =AB36-Y36 -> 3740.7086 | AF36: =PI()*(Z36+AA36)/2000*(X36/1000)*(V36-W36)*7850 -> 5562.2944 | AI36: 72.7 | AJ36: 70.15 | AK36: 24 | AL36: 24 | AM36: 4144.4459 | AN36: 4096.4459 | AO36: 4287.5058 | AP36: 4239.5058 | AT36: 28 | AU36: =IF('20251110-불일치 수정'!F36=AM36,"-","CHANGE") -> - | AV36: =IF('20251110-불일치 수정'!G36=AN36,"-","CHANGE") -> - | AW36: =IF('20251110-불일치 수정'!H36=AO36,"-","CHANGE") -> - | AX36: =IF('20251110-불일치 수정'!I36=AP36,"-","CHANGE") -> -
B37: 75.25 | C37: 72.7 | D37: 23 | E37: 23 | F37: 3630.064 | G37: 3584.064 | H37: 3697.3863 | I37: 3651.3863 | L37: =PI()*(F37+G37)/2000*(D37/1000)*(B37-C37)*7850 -> 5217.247 | M37: =B37-$C$9 -> 60.25 | N37: =F37 -> 3630.064 | O37: =H37 -> 3697.3863 | P37: 23 | Q37: =PI()/4*((N37/2000)^4-(N37/2000-P37/1000)^4) -> 0.42390343 | R37: 3630.064 | S37: 23 | T37: =PI()/4*((R37/2000)^4-(R37/2000-S37/1000)^4) -> 0.42390343 | V37: =B37 -> 75.25 | W37: =C37 -> 72.7 | X37: =S37 -> 23 | Y37: =S37 -> 23 | Z37: =R37 -> 3630.064 | AA37: =Z37-X37 -> 3607.064 | AB37: =Z36 -> 3697.3863 | AC37: =AB37-Y37 -> 3674.3863 | AF37: =PI()*(Z37+AA37)/2000*(X37/1000)*(V37-W37)*7850 -> 5233.8806 | AI37: 75.25 | AJ37: 72.7 | AK37: 23 | AL37: 23 | AM37: 4001.386 | AN37: 3955.386 | AO37: 4144.4459 | AP37: 4098.4459 | AT37: 29 | AU37: =IF('20251110-불일치 수정'!F37=AM37,"-","CHANGE") -> - | AV37: =IF('20251110-불일치 수정'!G37=AN37,"-","CHANGE") -> - | AW37: =IF('20251110-불일치 수정'!H37=AO37,"-","CHANGE") -> - | AX37: =IF('20251110-불일치 수정'!I37=AP37,"-","CHANGE") -> -
B38: 77.8 | C38: 75.25 | D38: 23 | E38: 23 | F38: 3562.7417 | G38: 3516.7417 | H38: 3630.064 | I38: 3584.064 | L38: =PI()*(F38+G38)/2000*(D38/1000)*(B38-C38)*7850 -> 5119.8722 | M38: =B38-$C$9 -> 62.8 | N38: =F38 -> 3562.7417 | O38: =H38 -> 3630.064 | P38: 23 | Q38: =PI()/4*((N38/2000)^4-(N38/2000-P38/1000)^4) -> 0.40060908 | R38: 3562.7417 | S38: 23 | T38: =PI()/4*((R38/2000)^4-(R38/2000-S38/1000)^4) -> 0.40060908 | V38: =B38 -> 77.8 | W38: =C38 -> 75.25 | X38: =S38 -> 23 | Y38: =S38 -> 23 | Z38: =R38 -> 3562.7417 | AA38: =Z38-X38 -> 3539.7417 | AB38: =Z37 -> 3630.064 | AC38: =AB38-Y38 -> 3607.064 | AF38: =PI()*(Z38+AA38)/2000*(X38/1000)*(V38-W38)*7850 -> 5136.5058 | AI38: 77.8 | AJ38: 75.25 | AK38: 23 | AL38: 23 | AM38: 3858.3262 | AN38: 3812.3262 | AO38: 4001.386 | AP38: 3955.386 | AT38: 30 | AU38: =IF('20251110-불일치 수정'!F38=AM38,"-","CHANGE") -> - | AV38: =IF('20251110-불일치 수정'!G38=AN38,"-","CHANGE") -> - | AW38: =IF('20251110-불일치 수정'!H38=AO38,"-","CHANGE") -> - | AX38: =IF('20251110-불일치 수정'!I38=AP38,"-","CHANGE") -> -
B39: 80.35 | C39: 77.8 | D39: 21 | E39: 21 | F39: 3495.4194 | G39: 3453.4194 | H39: 3562.7417 | I39: 3520.7417 | L39: =PI()*(F39+G39)/2000*(D39/1000)*(B39-C39)*7850 -> 4588.3998 | M39: =B39-$C$9 -> 65.35 | N39: =F39 -> 3495.4194 | O39: =H39 -> 3562.7417 | P39: 21 | Q39: =PI()/4*((N39/2000)^4-(N39/2000-P39/1000)^4) -> 0.34589301 | R39: 3495.4194 | S39: 21 | T39: =PI()/4*((R39/2000)^4-(R39/2000-S39/1000)^4) -> 0.34589301 | V39: =B39 -> 80.35 | W39: =C39 -> 77.8 | X39: =S39 -> 21 | Y39: =S39 -> 21 | Z39: =R39 -> 3495.4194 | AA39: =Z39-X39 -> 3474.4194 | AB39: =Z38 -> 3562.7417 | AC39: =AB39-Y39 -> 3541.7417 | AF39: =PI()*(Z39+AA39)/2000*(X39/1000)*(V39-W39)*7850 -> 4602.2663 | AI39: 80.35 | AJ39: 77.8 | AK39: 21 | AL39: 21 | AM39: 3715.2663 | AN39: 3673.2663 | AO39: 3858.3262 | AP39: 3816.3262 | AT39: 31 | AU39: =IF('20251110-불일치 수정'!F39=AM39,"-","CHANGE") -> - | AV39: =IF('20251110-불일치 수정'!G39=AN39,"-","CHANGE") -> - | AW39: =IF('20251110-불일치 수정'!H39=AO39,"-","CHANGE") -> - | AX39: =IF('20251110-불일치 수정'!I39=AP39,"-","CHANGE") -> -
B40: 82.9 | C40: 80.35 | D40: 20 | E40: 20 | F40: 3428.0972 | G40: 3388.0972 | H40: 3495.4194 | I40: 3455.4194 | L40: =PI()*(F40+G40)/2000*(D40/1000)*(B40-C40)*7850 -> 4286.4886 | M40: =B40-$C$9 -> 67.9 | N40: =F40 -> 3428.0972 | O40: =H40 -> 3495.4194 | P40: 20 | Q40: =PI()/4*((N40/2000)^4-(N40/2000-P40/1000)^4) -> 0.31091433 | R40: 3428.0972 | S40: 20 | T40: =PI()/4*((R40/2000)^4-(R40/2000-S40/1000)^4) -> 0.31091433 | V40: =B40 -> 82.9 | W40: =C40 -> 80.35 | X40: =S40 -> 20 | Y40: =S40 -> 20 | Z40: =R40 -> 3428.0972 | AA40: =Z40-X40 -> 3408.0972 | AB40: =Z39 -> 3495.4194 | AC40: =AB40-Y40 -> 3475.4194 | AF40: =PI()*(Z40+AA40)/2000*(X40/1000)*(V40-W40)*7850 -> 4299.066 | AI40: 82.9 | AJ40: 80.35 | AK40: 20 | AL40: 20 | AM40: 3572.2065 | AN40: 3532.2065 | AO40: 3715.2663 | AP40: 3675.2663 | AT40: 32 | AU40: =IF('20251110-불일치 수정'!F40=AM40,"-","CHANGE") -> - | AV40: =IF('20251110-불일치 수정'!G40=AN40,"-","CHANGE") -> - | AW40: =IF('20251110-불일치 수정'!H40=AO40,"-","CHANGE") -> - | AX40: =IF('20251110-불일치 수정'!I40=AP40,"-","CHANGE") -> -
B41: 85.226 | C41: 82.9 | D41: 19 | E41: 19 | F41: 3366.6887 | G41: 3328.6887 | H41: 3428.0972 | I41: 3390.0972 | L41: =PI()*(F41+G41)/2000*(D41/1000)*(B41-C41)*7850 -> 3648.6139 | M41: =B41-$C$9 -> 70.226 | N41: =F41 -> 3366.6887 | O41: =H41 -> 3428.0972 | P41: 19 | Q41: =PI()/4*((N41/2000)^4-(N41/2000-P41/1000)^4) -> 0.27993852 | R41: 3366.6887 | S41: 19 | T41: =PI()/4*((R41/2000)^4-(R41/2000-S41/1000)^4) -> 0.27993852 | V41: =B41 -> 85.226 | W41: =C41 -> 82.9 | X41: =S41 -> 19 | Y41: =S41 -> 19 | Z41: =R41 -> 3366.6887 | AA41: =Z41-X41 -> 3347.6887 | AB41: =Z40 -> 3428.0972 | AC41: =AB41-Y41 -> 3409.0972 | AF41: =PI()*(Z41+AA41)/2000*(X41/1000)*(V41-W41)*7850 -> 3658.9678 | AI41: 85.226 | AJ41: 82.9 | AK41: 19 | AL41: 19 | AM41: 3441.7134 | AN41: 3403.7134 | AO41: 3572.2065 | AP41: 3534.2065 | AT41: 33 | AU41: =IF('20251110-불일치 수정'!F41=AM41,"-","CHANGE") -> - | AV41: =IF('20251110-불일치 수정'!G41=AN41,"-","CHANGE") -> - | AW41: =IF('20251110-불일치 수정'!H41=AO41,"-","CHANGE") -> - | AX41: =IF('20251110-불일치 수정'!I41=AP41,"-","CHANGE") -> -
...

Sheet 20251110-불일치 수정
B2: 부유식 모델 2차_251110 - 일부 불일치 수정 (Inner dia 불일치)
B3: Upper | C3: Lower | D3: Upper | E3: Lower | F3: Upper | G3: Upper | H3: Lower | I3: Lower | J3: Flange | K3: Flange
B4: height | C4: height | D4: Wall | E4: Wall | F4: outside | G4: inside | H4: outside | I4: inside | J4: Location | K4: Mass
B5: above | C5: above | D5: thick- | E5: thick- | F5: diameter, | G5: diameter, | H5: diameter, | I5: diameter,
B6: ground, | C6: ground, | D6: ness, | E6: ness, | F6: DO,i_UPR | G6: DI,i_UPR | H6: DO,i_LWR | I6: DI,i_LWR
B7: Hi_UPR | C7: Hi_LWR | D7: ti | E7: ti | L7: 무게
B8: [m] | C8: [m] | D8: [mm] | E8: [mm] | F8: [m] | G8: [m] | H8: [m] | I8: [m] | J8: [-] | K8: [kg] | L8: kg
B9: 15.3 | C9: 15 | D9: 36 | E9: 36 | F9: 5000 | G9: =F9-2*D9 -> 4928 | H9: 5000 | I9: =H9-2*E9 -> 4928 | J9: L-FLG | K9: 7439.1662 | L9: =1/3*PI()*(B9-C9)*((F9/2000)^2+(F9/2000*H9/2000)+(H9/2000)^2-((G9/2000)^2+(G9/2000*I9/2000)+(I9/2000)^2))*7850 -> 1322.1327
B10: 17.4 | C10: 15.3 | D10: 35 | E10: 35 | F10: 5000 | G10: =F10-2*D10 -> 4930 | H10: 5000 | I10: =H10-2*E10 -> 4930 | L10: =1/3*PI()*(B10-C10)*((F10/2000)^2+(F10/2000*H10/2000)+(H10/2000)^2-((G10/2000)^2+(G10/2000*I10/2000)+(I10/2000)^2))*7850 -> 8999.6604
B11: 19.5 | C11: 17.4 | D11: 34 | E11: 34 | F11: 5000 | G11: =F11-2*D11 -> 4932 | H11: 5000 | I11: =H11-2*E11 -> 4932 | L11: =1/3*PI()*(B11-C11)*((F11/2000)^2+(F11/2000*H11/2000)+(H11/2000)^2-((G11/2000)^2+(G11/2000*I11/2000)+(I11/2000)^2))*7850 -> 8744.2881
B12: 21.6 | C12: 19.5 | D12: 34 | E12: 34 | F12: 5000 | G12: =F12-2*D12 -> 4932 | H12: 5000 | I12: =H12-2*E12 -> 4932 | L12: =1/3*PI()*(B12-C12)*((F12/2000)^2+(F12/2000*H12/2000)+(H12/2000)^2-((G12/2000)^2+(G12/2000*I12/2000)+(I12/2000)^2))*7850 -> 8744.2881
B13: 23.7 | C13: 21.6 | D13: 34 | E13: 34 | F13: 5000 | G13: =F13-2*D13 -> 4932 | H13: 5000 | I13: =H13-2*E13 -> 4932 | L13: =1/3*PI()*(B13-C13)*((F13/2000)^2+(F13/2000*H13/2000)+(H13/2000)^2-((G13/2000)^2+(G13/2000*I13/2000)+(I13/2000)^2))*7850 -> 8744.2881
B14: 25.8 | C14: 23.7 | D14: 33 | E14: 33 | F14: 5000 | G14: =F14-2*D14 -> 4934 | H14: 5000 | I14: =H14-2*E14 -> 4934 | L14: =1/3*PI()*(B14-C14)*((F14/2000)^2+(F14/2000*H14/2000)+(H14/2000)^2-((G14/2000)^2+(G14/2000*I14/2000)+(I14/2000)^2))*7850 -> 8488.8122
B15: 28.4 | C15: 25.8 | D15: 32 | E15: 32 | F15: 5000 | G15: =F15-2*D15 -> 4936 | H15: 5000 | I15: =H15-2*E15 -> 4936 | L15: =1/3*PI()*(B15-C15)*((F15/2000)^2+(F15/2000*H15/2000)+(H15/2000)^2-((G15/2000)^2+(G15/2000*I15/2000)+(I15/2000)^2))*7850 -> 10193.526
B16: 31 | C16: 28.4 | D16: 31 | E16: 31 | F16: 5000 | G16: =F16-2*D16 -> 4938 | H16: 5000 | I16: =H16-2*E16 -> 4938 | L16: =1/3*PI()*(B16-C16)*((F16/2000)^2+(F16/2000*H16/2000)+(H16/2000)^2-((G16/2000)^2+(G16/2000*I16/2000)+(I16/2000)^2))*7850 -> 9876.9662
B17: 33.6 | C17: 31 | D17: 31 | E17: 31 | F17: 5000 | G17: =F17-2*D17 -> 4938 | H17: 5000 | I17: =H17-2*E17 -> 4938 | L17: =1/3*PI()*(B17-C17)*((F17/2000)^2+(F17/2000*H17/2000)+(H17/2000)^2-((G17/2000)^2+(G17/2000*I17/2000)+(I17/2000)^2))*7850 -> 9876.9662
B18: 36.2 | C18: 33.6 | D18: 30 | E18: 30 | F18: 5000 | G18: =F18-2*D18 -> 4940 | H18: 5000 | I18: =H18-2*E18 -> 4940 | L18: =1/3*PI()*(B18-C18)*((F18/2000)^2+(F18/2000*H18/2000)+(H18/2000)^2-((G18/2000)^2+(G18/2000*I18/2000)+(I18/2000)^2))*7850 -> 9560.278
B19: 38.75 | C19: 36.2 | D19: 29 | E19: 29 | F19: 5000 | G19: =F19-2*D19 -> 4942 | H19: 5000 | I19: =H19-2*E19 -> 4942 | L19: =1/3*PI()*(B19-C19)*((F19/2000)^2+(F19/2000*H19/2000)+(H19/2000)^2-((G19/2000)^2+(G19/2000*I19/2000)+(I19/2000)^2))*7850 -> 9065.7027
B20: 39 | C20: 38.75 | D20: 29 | E20: 29 | F20: 5000 | G20: =F20-2*D20 -> 4942 | H20: 5000 | I20: =H20-2*E20 -> 4942 | J20: L-FLG | K20: 3441.0786 | L20: =1/3*PI()*(B20-C20)*((F20/2000)^2+(F20/2000*H20/2000)+(H20/2000)^2-((G20/2000)^2+(G20/2000*I20/2000)+(I20/2000)^2))*7850 -> 888.79438
B21: 39.25 | C21: 39 | D21: 28 | E21: 28 | F21: 5000 | G21: =F21-2*D21 -> 4944 | H21: 5000 | I21: =H21-2*E21 -> 4944 | J21: L-FLG | K21: 3441.0786 | L21: =1/3*PI()*(B21-C21)*((F21/2000)^2+(F21/2000*H21/2000)+(H21/2000)^2-((G21/2000)^2+(G21/2000*I21/2000)+(I21/2000)^2))*7850 -> 858.31893
B22: 41.75 | C22: 39.25 | D22: 28 | E22: 28 | F22: 5000 | G22: =F22-2*D22 -> 4944 | H22: 5000 | I22: =H22-2*E22 -> 4944 | L22: =1/3*PI()*(B22-C22)*((F22/2000)^2+(F22/2000*H22/2000)+(H22/2000)^2-((G22/2000)^2+(G22/2000*I22/2000)+(I22/2000)^2))*7850 -> 8583.1893
B23: 44.3 | C23: 41.75 | D23: 27 | E23: 27 | F23: 5000 | G23: =F23-2*D23 -> 4946 | H23: 5000 | I23: =H23-2*E23 -> 4946 | L23: =1/3*PI()*(B23-C23)*((F23/2000)^2+(F23/2000*H23/2000)+(H23/2000)^2-((G23/2000)^2+(G23/2000*I23/2000)+(I23/2000)^2))*7850 -> 8443.8777
B24: 46.85 | C24: 44.3 | D24: 26 | E24: 26 | F24: 5000 | G24: =F24-2*D24 -> 4948 | H24: 5000 | I24: =H24-2*E24 -> 4948 | L24: =1/3*PI()*(B24-C24)*((F24/2000)^2+(F24/2000*H24/2000)+(H24/2000)^2-((G24/2000)^2+(G24/2000*I24/2000)+(I24/2000)^2))*7850 -> 8132.7765
B25: 49.4 | C25: 46.85 | D25: 26 | E25: 26 | F25: 5000 | G25: =F25-2*D25 -> 4948 | H25: 5000 | I25: =H25-2*E25 -> 4948 | L25: =1/3*PI()*(B25-C25)*((F25/2000)^2+(F25/2000*H25/2000)+(H25/2000)^2-((G25/2000)^2+(G25/2000*I25/2000)+(I25/2000)^2))*7850 -> 8132.7765
B26: 51.95 | C26: 49.4 | D26: 25 | E26: 25 | F26: 5000 | G26: =F26-2*D26 -> 4950 | H26: 5000 | I26: =H26-2*E26 -> 4950 | L26: =1/3*PI()*(B26-C26)*((F26/2000)^2+(F26/2000*H26/2000)+(H26/2000)^2-((G26/2000)^2+(G26/2000*I26/2000)+(I26/2000)^2))*7850 -> 7821.5496
B27: 54.5 | C27: 51.95 | D27: 24 | E27: 24 | F27: 5000 | G27: =F27-2*D27 -> 4952 | H27: 5000 | I27: =H27-2*E27 -> 4952 | L27: =1/3*PI()*(B27-C27)*((F27/2000)^2+(F27/2000*H27/2000)+(H27/2000)^2-((G27/2000)^2+(G27/2000*I27/2000)+(I27/2000)^2))*7850 -> 7510.1969
B28: 57 | C28: 54.5 | D28: 23 | E28: 23 | F28: 5000 | G28: =F28-2*D28 -> 4954 | H28: 5000 | I28: =H28-2*E28 -> 4954 | L28: =1/3*PI()*(B28-C28)*((F28/2000)^2+(F28/2000*H28/2000)+(H28/2000)^2-((G28/2000)^2+(G28/2000*I28/2000)+(I28/2000)^2))*7850 -> 7057.5671
B29: 57.225 | C29: 57 | D29: 22 | E29: 22 | F29: 5000 | G29: =F29-2*D29 -> 4956 | H29: 5000 | I29: =H29-2*E29 -> 4956 | J29: L-FLG | K29: 3146.132 | L29: =1/3*PI()*(B29-C29)*((F29/2000)^2+(F29/2000*H29/2000)+(H29/2000)^2-((G29/2000)^2+(G29/2000*I29/2000)+(I29/2000)^2))*7850 -> 607.68655
B30: 57.45 | C30: 57.225 | D30: 22 | E30: 22 | F30: 5000 | G30: =F30-2*D30 -> 4956 | H30: 5000 | I30: =H30-2*E30 -> 4956 | J30: L-FLG | K30: 3146.132 | L30: =1/3*PI()*(B30-C30)*((F30/2000)^2+(F30/2000*H30/2000)+(H30/2000)^2-((G30/2000)^2+(G30/2000*I30/2000)+(I30/2000)^2))*7850 -> 607.68655
B31: 59.95 | C31: 57.45 | D31: 22 | E31: 22 | F31: 4859.7452 | G31: =F31-2*D31 -> 4815.7452 | H31: 5000 | I31: =H31-2*E31 -> 4956 | L31: =1/3*PI()*(B31-C31)*((F31/2000)^2+(F31/2000*H31/2000)+(H31/2000)^2-((G31/2000)^2+(G31/2000*I31/2000)+(I31/2000)^2))*7850 -> 6656.9532
B32: 62.5 | C32: 59.95 | D32: 22 | E32: 22 | F32: 4716.6854 | G32: =F32-2*D32 -> 4672.6854 | H32: 4859.7452 | I32: =H32-2*E32 -> 4815.7452 | L32: =1/3*PI()*(B32-C32)*((F32/2000)^2+(F32/2000*H32/2000)+(H32/2000)^2-((G32/2000)^2+(G32/2000*I32/2000)+(I32/2000)^2))*7850 -> 6594.1079
B33: 65.05 | C33: 62.5 | D33: 22 | E33: 22 | F33: 4573.6255 | G33: =F33-2*D33 -> 4529.6255 | H33: 4716.6854 | I33: =H33-2*E33 -> 4672.6854 | L33: =1/3*PI()*(B33-C33)*((F33/2000)^2+(F33/2000*H33/2000)+(H33/2000)^2-((G33/2000)^2+(G33/2000*I33/2000)+(I33/2000)^2))*7850 -> 6396.1831
B34: 67.6 | C34: 65.05 | D34: 23 | E34: 23 | F34: 4430.5656 | G34: =F34-2*D34 -> 4384.5656 | H34: 4573.6255 | I34: =H34-2*E34 -> 4527.6255 | L34: =1/3*PI()*(B34-C34)*((F34/2000)^2+(F34/2000*H34/2000)+(H34/2000)^2-((G34/2000)^2+(G34/2000*I34/2000)+(I34/2000)^2))*7850 -> 6478.5509
B35: 70.15 | C35: 67.6 | D35: 25 | E35: 25 | F35: 4287.5058 | G35: =F35-2*D35 -> 4237.5058 | H35: 4430.5656 | I35: =H35-2*E35 -> 4380.5656 | L35: =1/3*PI()*(B35-C35)*((F35/2000)^2+(F35/2000*H35/2000)+(H35/2000)^2-((G35/2000)^2+(G35/2000*I35/2000)+(I35/2000)^2))*7850 -> 6813.8443
B36: 72.7 | C36: 70.15 | D36: 24 | E36: 24 | F36: 4144.4459 | G36: =F36-2*D36 -> 4096.4459 | H36: 4287.5058 | I36: =H36-2*E36 -> 4239.5058 | L36: =1/3*PI()*(B36-C36)*((F36/2000)^2+(F36/2000*H36/2000)+(H36/2000)^2-((G36/2000)^2+(G36/2000*I36/2000)+(I36/2000)^2))*7850 -> 6326.8818
B37: 75.25 | C37: 72.7 | D37: 23 | E37: 23 | F37: 4001.386 | G37: =F37-2*D37 -> 3955.386 | H37: 4144.4459 | I37: =H37-2*E37 -> 4098.4459 | L37: =1/3*PI()*(B37-C37)*((F37/2000)^2+(F37/2000*H37/2000)+(H37/2000)^2-((G37/2000)^2+(G37/2000*I37/2000)+(I37/2000)^2))*7850 -> 5857.7868
B38: 77.8 | C38: 75.25 | D38: 23 | E38: 23 | F38: 3858.3262 | G38: =F38-2*D38 -> 3812.3262 | H38: 4001.386 | I38: =H38-2*E38 -> 3955.386 | L38: =1/3*PI()*(B38-C38)*((F38/2000)^2+(F38/2000*H38/2000)+(H38/2000)^2-((G38/2000)^2+(G38/2000*I38/2000)+(I38/2000)^2))*7850 -> 5650.8654
B39: 80.35 | C39: 77.8 | D39: 21 | E39: 21 | F39: 3715.2663 | G39: =F39-2*D39 -> 3673.2663 | H39: 3858.3262 | I39: =H39-2*E39 -> 3816.3262 | L39: =1/3*PI()*(B39-C39)*((F39/2000)^2+(F39/2000*H39/2000)+(H39/2000)^2-((G39/2000)^2+(G39/2000*I39/2000)+(I39/2000)^2))*7850 -> 4973.1988
